Workbook

Sheet Hoja1
A1: Módulo / Atlas de Igualdad y Derechos Humanos | M1: 45536
A2: LISTADO DE INDICADORES Y SUS FICHAS TÉCNICAS
A4: Comisión Nacional de Derechos Humanos I Cuarta Visitaduría General I Programa de Asunto de la Mujer y de Igualdad entre Mujeres y Hombres
A5: Dirección General de Planeación y Estrategia Institucional I Centro de Análisis de Información Geoespacial
A6: ATLAS | E6: FICHAS TÉCNICAS
A8: ID | B8: Dimensión | C8: Indicador | D8: Subindicador I | E8: Nombre: | F8: Datos disponibles: | G8: Desagregación geográfica: | H8: Definición: | I8: Desagregación: | J8: Forma de cálculo: | K8: Unidad del Estado responsable del cálculo: | L8: Unidad de medida: | M8: Periodicidad: | N8: Fuente de información: | O8: Articulación jurídica: | P8: Observaciones: | Q8: Consideraciones
A9: 1 | B9: Demográfica | C9: Población por sexo | D9: Población estatal | E9: =[1]Demográfica!D4 -> Población por entidad federativa. | F9: =[1]Demográfica!E4 -> 2005, 2010, 2015 y 2020. | G9: =[1]Demográfica!F4 -> Estatal | H9: =[1]Demográfica!G4 -> Total de población que reside habitualmente en la vivienda en la fecha de referencia al levantamiento por entidad federativa. | I9: =[1]Demográfica!H4 -> No aplica. | J9: =[1]Demográfica!I4 -> Suma de la población total (con estimación) de la unidad administrativa. | K9: =[1]Demográfica!J4 -> Cálculos por el Colegio de Geografía (UNAM) y de la CNDH a partir de la información del Instituto Nacional de Estadística y Geografía (INEGI) | L9: =[1]Demográfica!K4 -> Absolutos | ... P9: =[1]Demográfica!O4 -> Notas INEGI: Derivado de la sentencia emitida por el Pleno de la Suprema Corte de Justicia de la Nación respecto a la Controversia Constitucional 41/2011, se publican, con fecha 26 de junio de 2013, todos los resultados del Censo de Población y Vivienda 2010 para los municipios de Tultepec, Nextlalpan y Tultitlán, estado de México. Para 2020, la información está referida al 15 de marzo. Incluye una estimación de población de 6 337 751 personas que corresponden a 1 588 422 Viviendas sin información de ocupantes. | Q9: =[1]Demográfica!AD4 -> Datos vigentes por periodicidad quinquenal.
A10: 2 | B10: Demográfica | C10: Población por sexo | D10: Población estatal de mujeres | E10: =[1]Demográfica!D5 -> Población de mujeres, por entidad federativa. | F10: =[1]Demográfica!E5 -> 2005, 2010, 2015 y 2020. | G10: =[1]Demográfica!F5 -> Estatal | H10: =[1]Demográfica!G5 -> Total de población de mujeres que reside habitualmente en la vivienda en la fecha de referencia al levantamiento por entidad federativa. | I10: =[1]Demográfica!H5 -> Por sexo | J10: =[1]Demográfica!I5 -> Suma de la población según sexo (mujeres/hombres) (con estimación) de la unidad administrativa. | K10: =[1]Demográfica!J5 -> Cálculos por el Colegio de Geografía (UNAM) y de la CNDH a partir de la información del Instituto Nacional de Estadística y Geografía (INEGI) | L10: =[1]Demográfica!K5 -> Absolutos | ... P10: =[1]Demográfica!O5 -> Notas INEGI: Derivado de la sentencia emitida por el Pleno de la Suprema Corte de Justicia de la Nación respecto a la Controversia Constitucional 41/2011, se publican, con fecha 26 de junio de 2013, todos los resultados del Censo de Población y Vivienda 2010 para los municipios de Tultepec, Nextlalpan y Tultitlán, estado de México. Para 2020, la información está referida al 15 de marzo. Incluye una estimación de población de 6 337 751 personas que corresponden a 1 588 422 Viviendas sin información de ocupantes. | Q10: =[1]Demográfica!AD5 -> Datos vigentes por periodicidad quinquenal.
A11: 3 | B11: Demográfica | C11: Población por sexo | D11: Población estatal de hombres | E11: =[1]Demográfica!D6 -> Población de hombres, por entidad federativa. | F11: =[1]Demográfica!E6 -> 2005, 2010, 2015 y 2020. | G11: =[1]Demográfica!F6 -> Estatal | H11: =[1]Demográfica!G6 -> Total de población de hombres que reside habitualmente en la vivienda en la fecha de referencia al levantamiento por entidad federativa. | I11: =[1]Demográfica!H6 -> Por sexo | J11: =[1]Demográfica!I6 -> Suma de la población según sexo (mujeres/hombres) (con estimación) de la unidad administrativa. | K11: =[1]Demográfica!J6 -> Cálculos por el Colegio de Geografía (UNAM) y de la CNDH a partir de la información del Instituto Nacional de Estadística y Geografía (INEGI) | L11: =[1]Demográfica!K6 -> Absolutos | ... P11: =[1]Demográfica!O6 -> Notas INEGI: Derivado de la sentencia emitida por el Pleno de la Suprema Corte de Justicia de la Nación respecto a la Controversia Constitucional 41/2011, se publican, con fecha 26 de junio de 2013, todos los resultados del Censo de Población y Vivienda 2010 para los municipios de Tultepec, Nextlalpan y Tultitlán, estado de México. Para 2020, la información está referida al 15 de marzo. Incluye una estimación de población de 6 337 751 personas que corresponden a 1 588 422 Viviendas sin información de ocupantes. | Q11: =[1]Demográfica!AD6 -> Datos vigentes por periodicidad quinquenal.
A12: 4 | B12: Demográfica | C12: Población que habla lengua indígena por sexo | D12: Población estatal que habla lengua indígena | E12: =[1]Demográfica!D7 -> Población que habla lengua indígena, por entidad federativa. | F12: =[1]Demográfica!E7 -> 2005, 2010, 2015 y 2020. | G12: =[1]Demográfica!F7 -> Estatal | H12: =[1]Demográfica!G7 -> Total de población de 5 años y más (o 3 años y más, cuando corresponda) que habla lengua indígena, incluyendo lenguas originarias de otros países Latinoamericanos, en la fecha de referencia al levantamiento por entidad federativa. | I12: =[1]Demográfica!H7 -> No aplica. | J12: =[1]Demográfica!I7 -> Suma de la población total de 5 años y más (o 3 años y más, cuando corresponda) que habla lengua indígena. | K12: =[1]Demográfica!J7 -> Cálculos por el Colegio de Geografía (UNAM) y de la CNDH a partir de la información del Instituto Nacional de Estadística y Geografía (INEGI) | L12: =[1]Demográfica!K7 -> Absolutos | ... P12: =[1]Demográfica!O7 -> Para 2005 la información está referida a la población de 5 años y más, mientras que para 2010 para la población de 3 años y más. Nota INEGI: Derivado de la sentencia emitida por el Pleno de la Suprema Corte de Justicia de la Nación respecto a la Controversia Constitucional 41/2011, se publican, con fecha 26 de junio de 2013, todos los resultados del Censo de Población y Vivienda 2010 para los municipios de Tultepec, Nextlalpan y Tultitlán, estado de México. | Q12: =[1]Demográfica!AD7 -> Datos vigentes por periodicidad quinquenal.
A13: 5 | B13: Demográfica | C13: Población que habla lengua indígena por sexo | D13: Población estatal de mujeres que habla lengua indígena | E13: =[1]Demográfica!D8 -> Población de mujeres que habla lengua indígena, por entidad federativa. | F13: =[1]Demográfica!E8 -> 2005, 2010, 2015 y 2020. | G13: =[1]Demográfica!F8 -> Estatal | H13: =[1]Demográfica!G8 -> Total de población de niñas y mujeres de 5 años y más (o 3 años y más, cuando corresponda) que hablan lengua indígena, incluyendo lenguas originarias de otros países Latinoamericanos, en la fecha de referencia al levantamiento por entidad federativa. | I13: =[1]Demográfica!H8 -> Por sexo | J13: =[1]Demográfica!I8 -> Suma de la población según sexo (mujeres/hombres) de 5 años y más (o 3 años y más, cuando corresponda) que habla lengua indígena. | K13: =[1]Demográfica!J8 -> Cálculos por el Colegio de Geografía (UNAM) y de la CNDH a partir de la información del Instituto Nacional de Estadística y Geografía (INEGI) | L13: =[1]Demográfica!K8 -> Absolutos | ... P13: =[1]Demográfica!O8 -> Para 2005 la información está referida a la población de 5 años y más, mientras que para 2010 para la población de 3 años y más. Nota INEGI: Derivado de la sentencia emitida por el Pleno de la Suprema Corte de Justicia de la Nación respecto a la Controversia Constitucional 41/2011, se publican, con fecha 26 de junio de 2013, todos los resultados del Censo de Población y Vivienda 2010 para los municipios de Tultepec, Nextlalpan y Tultitlán, estado de México. | Q13: =[1]Demográfica!AD8 -> Datos vigentes por periodicidad quinquenal.
A14: 6 | B14: Demográfica | C14: Población que habla lengua indígena por sexo | D14: Población estatal de hombres que habla lengua indígena | E14: =[1]Demográfica!D9 -> Población de hombres que habla lengua indígena, por entidad federativa. | F14: =[1]Demográfica!E9 -> 2005, 2010, 2015 y 2020. | G14: =[1]Demográfica!F9 -> Estatal | H14: =[1]Demográfica!G9 -> Total de población de niños y hombres de 5 años y más (o 3 años y más, cuando corresponda) que hablan lengua indígena, incluyendo lenguas originarias de otros países Latinoamericanos, en la fecha de referencia al levantamiento por entidad federativa. | I14: =[1]Demográfica!H9 -> Por sexo | J14: =[1]Demográfica!I9 -> Suma de la población según sexo (mujeres/hombres) de 5 años y más (o 3 años y más, cuando corresponda) que habla lengua indígena. | K14: =[1]Demográfica!J9 -> Cálculos por el Colegio de Geografía (UNAM) y de la CNDH a partir de la información del Instituto Nacional de Estadística y Geografía (INEGI) | L14: =[1]Demográfica!K9 -> Absolutos | ... P14: =[1]Demográfica!O9 -> Para 2005 la información está referida a la población de 5 años y más, mientras que para 2010 para la población de 3 años y más. Nota INEGI: Derivado de la sentencia emitida por el Pleno de la Suprema Corte de Justicia de la Nación respecto a la Controversia Constitucional 41/2011, se publican, con fecha 26 de junio de 2013, todos los resultados del Censo de Población y Vivienda 2010 para los municipios de Tultepec, Nextlalpan y Tultitlán, estado de México. | Q14: =[1]Demográfica!AD9 -> Datos vigentes por periodicidad quinquenal.
A15: 7 | B15: Demográfica | C15: Densidad de población | D15: Densidad de población estatal | E15: =[1]Demográfica!D10 -> Densidad de población, por entidad federativa. | F15: =[1]Demográfica!E10 -> 2005, 2010, 2015 y 2020. | G15: =[1]Demográfica!F10 -> Estatal | H15: =[1]Demográfica!G10 -> Número de habitantes en función del área de un territorio determinado por kilómetro cuadrado, en la fecha de referencia al levantamiento por entidad federativa. | I15: =[1]Demográfica!H10 -> No aplica. | J15: =[1]Demográfica!I10 -> Cociente de la población total entre la superficie de la unidad administrativa. | K15: =[1]Demográfica!J10 -> Cálculos por el Colegio de Geografía (UNAM) y de la CNDH a partir de la información del Instituto Nacional de Estadística y Geografía (INEGI) | L15: =[1]Demográfica!K10 -> Habitantes por kilómetro cuadrado | ... P15: =[1]Demográfica!O10 -> 0 | Q15: =[1]Demográfica!AD10 -> Datos vigentes por periodicidad quinquenal.
A16: 8 | B16: Demográfica | C16: Índice de envejecimiento | D16: Índice de envejecimiento estatal | E16: =[1]Demográfica!D11 -> Índice de envejecimiento, por entidad federativa. | F16: =[1]Demográfica!E11 -> 2005, 2010, 2015 y 2020 | G16: =[1]Demográfica!F11 -> Estatal | H16: =[1]Demográfica!G11 -> Relación entre la cantidad de personas mayores (65 años y más) y la cantidad de personas en la niñez y adolescencia (0 a 14 años de edad), en la fecha de referencia al levantamiento por entidad federativa. | I16: =[1]Demográfica!H11 -> No aplica. | J16: =[1]Demográfica!I11 -> Suma de la población total de 65 años y más, entre la población total de 0 a 14 años, multiplicado por 100. | K16: =[1]Demográfica!J11 -> Cálculos por el Colegio de Geografía (UNAM) y de la CNDH a partir de la información del Instituto Nacional de Estadística y Geografía (INEGI) | L16: =[1]Demográfica!K11 -> Porcentaje | ... P16: =[1]Demográfica!O11 -> 0 | Q16: =[1]Demográfica!AD11 -> Datos vigentes por periodicidad quinquenal.
A17: 9 | B17: Demográfica | C17: Índice de envejecimiento | D17: Índice de envejecimiento estatal de mujeres | E17: =[1]Demográfica!D12 -> Índice de envejecimiento de mujeres, por entidad federativa. | F17: =[1]Demográfica!E12 -> 2005, 2010, 2015 y 2020 | G17: =[1]Demográfica!F12 -> Estatal | H17: =[1]Demográfica!G12 -> Relación entre la cantidad de mujeres mayores (65 años y más) y la cantidad de niñas y adolescentes (0 a 14 años de edad) en la fecha de referencia al levantamiento por entidad federativa. | I17: =[1]Demográfica!H12 -> Por sexo | J17: =[1]Demográfica!I12 -> Suma de la población total de mujeres de 65 años y más, entre la población total de niñas de 0 a 14 años, multiplicado por 100. | K17: =[1]Demográfica!J12 -> Cálculos por el Colegio de Geografía (UNAM) y de la CNDH a partir de la información del Instituto Nacional de Estadística y Geografía (INEGI) | L17: =[1]Demográfica!K12 -> Porcentaje | ... P17: =[1]Demográfica!O12 -> 0 | Q17: =[1]Demográfica!AD12 -> Datos vigentes por periodicidad quinquenal.
A18: 10 | B18: Demográfica | C18: Índice de envejecimiento | D18: Índice de envejecimiento estatal de hombres | E18: =[1]Demográfica!D13 -> Índice de envejecimiento de hombres, por entidad federativa. | F18: =[1]Demográfica!E13 -> 2005, 2010, 2015 y 2020 | G18: =[1]Demográfica!F13 -> Estatal | H18: =[1]Demográfica!G13 -> Relación entre la cantidad de hombres mayores (65 años y más) y la cantidad de niños y adolescentes (0 a 14 años de edad), en la fecha de referencia al levantamiento por entidad federativa. | I18: =[1]Demográfica!H13 -> Por sexo | J18: =[1]Demográfica!I13 -> Suma de la población total de hombres de 65 años y más, entre la población total de niños de 0 a 14 años, multiplicado por 100. | K18: =[1]Demográfica!J13 -> Cálculos por el Colegio de Geografía (UNAM) y de la CNDH a partir de la información del Instituto Nacional de Estadística y Geografía (INEGI) | L18: =[1]Demográfica!K13 -> Porcentaje | ... P18: =[1]Demográfica!O13 -> 0 | Q18: =[1]Demográfica!AD13 -> Datos vigentes por periodicidad quinquenal.
A19: 11 | B19: Demográfica | C19: Relación de dependencia | D19: Relación de dependencia estatal | E19: =[1]Demográfica!D14 -> Relación de dependencia, por entidad federativa. | F19: =[1]Demográfica!E14 -> 2005, 2010, 2015 y 2020. | G19: =[1]Demográfica!F14 -> Estatal | H19: =[1]Demográfica!G14 -> Relación entre el total de personas en edad económicamente inactiva (niños, niñas, adolescentes [0 a 14 años] y personas mayores [60 años y más]) y el total de personas en edad económicamente activa [15 a 59 años], en la fecha de referencia al levantamiento por entidad federativa. | I19: =[1]Demográfica!H14 -> No aplica. | J19: =[1]Demográfica!I14 -> Suma de la población total de 0 a 14 años más la población total de 60 años y más, entre la población total de 15 a 59, multiplicado por 100. [Por edad: dependencia infantil -en el numerador sólo se toma a la población de 0 a 14 años- y dependencia de adultos mayores -en el numerador sólo se toma a la población de 60 y más años). | K19: =[1]Demográfica!J14 -> Cálculos por el Colegio de Geografía (UNAM) y de la CNDH a partir de la información del Instituto Nacional de Estadística y Geografía (INEGI) | L19: =[1]Demográfica!K14 -> Porcentaje | ... P19: =[1]Demográfica!O14 -> Se trata de una relación potencial puesto que no todas las personas menores de 14 o mayores de 60 años está fuera del mercado laboral, ni todas las de 14-60 son activas (de hecho, la dependencia efectiva suele ser superior). No obstante, resume de manera aproximada la relación entre la magnitud de la fuerza de trabajo y la población pasiva, insumo a tener en cuenta en la formulación de políticas de empleo y de previsión social. | Q19: =[1]Demográfica!AD14 -> Datos vigentes por periodicidad quinquenal.
A20: 12 | B20: Demográfica | C20: Relación de dependencia | D20: Relación de dependencia estatal infantil | E20: =[1]Demográfica!D15 -> Relación de dependencia infantil, por entidad federativa. | F20: =[1]Demográfica!E15 -> 2005, 2010, 2015 y 2020. | G20: =[1]Demográfica!F15 -> Estatal | H20: =[1]Demográfica!G15 -> Relación entre el total de niñas, niños y adolescentes en edad económicamente inactiva [0 a 14 años] y el total de personas en edad económicamente activa [15 a 59 años], en la fecha de referencia al levantamiento por entidad federativa. | I20: =[1]Demográfica!H15 -> No aplica. | J20: =[1]Demográfica!I15 -> Suma de la población total de 0 a 14 años más la población total de 60 años y más, entre la población total de 15 a 59, multiplicado por 100. [Por edad: dependencia infantil -en el numerador sólo se toma a la población de 0 a 14 años- y dependencia de adultos mayores -en el numerador sólo se toma a la población de 60 y más años). | K20: =[1]Demográfica!J15 -> Cálculos por el Colegio de Geografía (UNAM) y de la CNDH a partir de la información del Instituto Nacional de Estadística y Geografía (INEGI) | L20: =[1]Demográfica!K15 -> Porcentaje | ... P20: =[1]Demográfica!O15 -> Se trata de una relación potencial puesto que no todas las personas menores de 14 o mayores de 60 años está fuera del mercado laboral, ni todas las de 14-60 son activas (de hecho, la dependencia efectiva suele ser superior). No obstante, resume de manera aproximada la relación entre la magnitud de la fuerza de trabajo y la población pasiva, insumo a tener en cuenta en la formulación de políticas de empleo y de previsión social. | Q20: =[1]Demográfica!AD15 -> Datos vigentes por periodicidad quinquenal.
... A30: 22 | B30: Demográfica | C30: Población con limitación y discapacidad según sexo | D30: Porcentaje estatal de hombres con limitación y discapacidad | E30: =[1]Demográfica!D25 -> Porcentaje de hombres con limitación y discapacidad, por entidad federativa. | F30: =[1]Demográfica!E25 -> 2014, 2018 y 2023 | G30: =[1]Demográfica!F25 -> Estatal | H30: =[1]Demográfica!G25 -> Distribución porcentual de hombres con alguna limitación, discapacidad o algún problema o condición mental, en la fecha de referencia al levantamiento por entidad federativa. | I30: =[1]Demográfica!H25 -> Por sexo | J30: =[1]Demográfica!I25 -> Suma de la población según sexo (mujeres/hombres) con alguna limitación, discapacidad o algún problema o condición mental, entre la población total según sexo (mujeres/hombres), multiplicado por 100. | K30: =[1]Demográfica!J25 -> Cálculos por el Colegio de Geografía (UNAM) y de la CNDH a partir de la información del Instituto Nacional de Estadística y Geografía (INEGI) | L30: =[1]Demográfica!K25 -> Porcentaje | ... P30: =[1]Demográfica!O25 -> La variable es la suma de "con discapacidad y con limitación". | Q30: =[1]Demográfica!AD25 -> Datos vigentes por periodicidad quinquenal.
A31: 23 | B31: Económica | C31: Población Económicamente Activa por grupo de edad según sexo | D31: Porcentaje estatal de mujeres económicamente activas de 20 a 29 años | E31: =[1]Económica!E4 -> Porcentaje de mujeres de 20 a 29 años de edad económicamente activa, por entidad federativa. | F31: =[1]Económica!F4 -> 2005, 2010, 2015 y 2020. | G31: =[1]Económica!G4 -> Estatal | H31: =[1]Económica!H4 -> Distribución porcentual de mujeres de 20 a 29 años de edad económicamente activa, es decir, que tuvieron vínculo con la actividad económica o que lo buscaron en la semana de referencia, por lo que se encontraban ocupadas o desocupadas, en la fecha de referencia al levantamiento por entidad federativa. | I31: =[1]Económica!I4 -> Por sexo y grupo de edad. | J31: =[1]Económica!J4 -> Promedio anual de la población económicamente activa según sexo (mujeres/hombres) y por grupos de edad correspondiente, entre el promedio anual de la población económicamente activa total, multiplicado por 100. | K31: =[1]Económica!K4 -> Cálculos por el Colegio de Geografía (UNAM) y de la CNDH a partir de la información del Instituto Nacional de Estadística y Geografía (INEGI) | L31: =[1]Económica!L4 -> Porcentaje | ... P31: =[1]Económica!P4 -> 1. Para el 2020, el promedio no integra el 2o trimestre por suspensión de la ENOE por contigencia sanitaria de COVID-19. 2. La fuente de información tiene periodicidad trimestral, pero para hacer manejable la cantidad de información, se determinó tomarla de manera quinquenal. | Q31: =[1]Económica!AE4 -> Datos vigentes por periodicidad quinquenal. La fuente de información tiene periodicidad trimestral, pero para hacer manejable la cantidad de información, se determinó tomarla de manera quinquenal.
A32: 24 | B32: Económica | C32: Población Económicamente Activa por grupo de edad según sexo | D32: Porcentaje estatal de hombres económicamente activos de 20 a 29 años | E32: =[1]Económica!E5 -> Porcentaje de hombres de 20 a 29 años de edad económicamente activa, por entidad federativa. | F32: =[1]Económica!F5 -> 2005, 2010, 2015 y 2020. | G32: =[1]Económica!G5 -> Estatal | H32: =[1]Económica!H5 -> Distribución porcentual de hombres de 20 a 29 años de edad económicamente activa, es decir, que tuvieron vínculo con la actividad económica o que lo buscaron en la semana de referencia, por lo que se encontraban ocupadas o desocupadas, en la fecha de referencia al levantamiento por entidad federativa. | I32: =[1]Económica!I5 -> Por sexo y grupo de edad. | J32: =[1]Económica!J5 -> Promedio anual de la población económicamente activa según sexo (mujeres/hombres) y por grupos de edad correspondiente, entre el promedio anual de la población económicamente activa total, multiplicado por 100. | K32: =[1]Económica!K5 -> Cálculos por el Colegio de Geografía (UNAM) y de la CNDH a partir de la información del Instituto Nacional de Estadística y Geografía (INEGI) | L32: =[1]Económica!L5 -> Porcentaje | ... P32: =[1]Económica!P5 -> 1. Para el 2020, el promedio no integra el 2o trimestre por suspensión de la ENOE por contigencia sanitaria de COVID-19. 2. La fuente de información tiene periodicidad trimestral, pero para hacer manejable la cantidad de información, se determinó tomarla de manera quinquenal. | Q32: =[1]Económica!AE5 -> Datos vigentes por periodicidad quinquenal. La fuente de información tiene periodicidad trimestral, pero para hacer manejable la cantidad de información, se determinó tomarla de manera quinquenal.
A33: 25 | B33: Económica | C33: Población asalariada y no asalariada según sexo | D33: Porcentaje estatal de la población trabajadora asalariada | E33: =[1]Económica!E6 -> Porcentaje de población trabajadora subordinada remunerada asalariada, por entidad federativa. | F33: =[1]Económica!F6 -> 2005, 2010, 2015 y 2020. | G33: =[1]Económica!G6 -> Estatal | H33: =[1]Económica!H6 -> Distribución porcentual de la población de 15 y más años de edad, que trabajaron para un patrón o empleador del sector privado o público; y que reciben un pago, sueldo, salario o jornal (subordinadas y remuneradas), en la fecha de referencia al levantamiento por entidad federativa. | I33: =[1]Económica!I6 -> Por posición en el trabajo. | J33: =[1]Económica!J6 -> Promedio anual de la población de 15 y más años de edad ocupada subordinada remunerada asalariada, es decir, que trabajaron para un patrón o empleador del sector privado o público; y que reciben un pago, sueldo, salario o jornal (subordinadas y remuneradas), entre el promedio anual de la población ocupada de cada entidad federativa (de los 4 trimestres) multiplicado por 100. | K33: =[1]Económica!K6 -> Cálculos por el Colegio de Geografía (UNAM) y de la CNDH a partir de la información del Instituto Nacional de Estadística y Geografía (INEGI) | L33: =[1]Económica!L6 -> Porcentaje | ... P33: =[1]Económica!P6 -> 1. Para el 2020, el promedio no integra el 2o trimestre por suspensión de la ENOE por contigencia sanitaria de COVID-19. 2. La fuente de información tiene periodicidad trimestral, pero para hacer manejable la cantidad de información, se determinó tomarla de manera quinquenal. | Q33: =[1]Económica!AE6 -> Datos vigentes por periodicidad quinquenal. La fuente de información tiene periodicidad trimestral, pero para hacer manejable la cantidad de información, se determinó tomarla de manera quinquenal.
A34: 26 | B34: Económica | C34: Población asalariada y no asalariada según sexo | D34: Porcentaje estatal de mujeres trabajadoras asalariadas | E34: =[1]Económica!E7 -> Porcentaje de mujeres trabajadoras subordinadas remuneradas asalariadas, por entidad federativa. | F34: =[1]Económica!F7 -> 2005, 2010, 2015 y 2020. | G34: =[1]Económica!G7 -> Estatal | H34: =[1]Económica!H7 -> Distribución porcentual de mujeres de 15 y más años de edad, que trabajaron para un patrón o empleador del sector privado o público; y que reciben un pago, sueldo, salario o jornal (subordinadas y remuneradas), en la fecha de referencia al levantamiento por entidad federativa. | I34: =[1]Económica!I7 -> Por sexo y posición en el trabajo. | J34: =[1]Económica!J7 -> Promedio anual de la población según sexo (mujeres/hombres) de 15 y más años de edad pcuáda subordinada remunerada asalariada, es decir, que trabajaron para un patrón o empleador del sector privado o público; y que reciben un pago, sueldo, salario o jornal (subordinadas y remuneradas), entre el promedio anual de la población ocupada de cada entidad federativa (de los 4 trimestres) multiplicado por 100. | K34: =[1]Económica!K7 -> Cálculos por el Colegio de Geografía (UNAM) y de la CNDH a partir de la información del Instituto Nacional de Estadística y Geografía (INEGI) | L34: =[1]Económica!L7 -> Porcentaje | ... P34: =[1]Económica!P7 -> 1. Para el 2020, el promedio no integra el 2o trimestre por suspensión de la ENOE por contigencia sanitaria de COVID-19. 2. La fuente de información tiene periodicidad trimestral, pero para hacer manejable la cantidad de información, se determinó tomarla de manera quinquenal. | Q34: =[1]Económica!AE7 -> Datos vigentes por periodicidad quinquenal. La fuente de información tiene periodicidad trimestral, pero para hacer manejable la cantidad de información, se determinó tomarla de manera quinquenal.
A35: 27 | B35: Económica | C35: Población asalariada y no asalariada según sexo | D35: Porcentaje estatal de hombres trabajadores asalariados | E35: =[1]Económica!E8 -> Porcentaje de hombres trabajadores subordinados remunerados asalariados, por entidad federativa. | F35: =[1]Económica!F8 -> 2005, 2010, 2015 y 2020. | G35: =[1]Económica!G8 -> Estatal | H35: =[1]Económica!H8 -> Distribución porcentual de hombres de 15 y más años de edad, que trabajaron para un patrón o empleador del sector privado o público; y que reciben un pago, sueldo, salario o jornal (subordinadas y remuneradas), en la fecha de referencia al levantamiento por entidad federativa. | I35: =[1]Económica!I8 -> Por sexo y posición en el trabajo. | J35: =[1]Económica!J8 -> Promedio anual de la población según sexo (mujeres/hombres) de 15 y más años de edad pcuáda subordinada remunerada asalariada, es decir, que trabajaron para un patrón o empleador del sector privado o público; y que reciben un pago, sueldo, salario o jornal (subordinadas y remuneradas), entre el promedio anual de la población ocupada de cada entidad federativa (de los 4 trimestres) multiplicado por 100. | K35: =[1]Económica!K8 -> Cálculos por el Colegio de Geografía (UNAM) y de la CNDH a partir de la información del Instituto Nacional de Estadística y Geografía (INEGI) | L35: =[1]Económica!L8 -> Porcentaje | ... P35: =[1]Económica!P8 -> 1. Para el 2020, el promedio no integra el 2o trimestre por suspensión de la ENOE por contigencia sanitaria de COVID-19. 2. La fuente de información tiene periodicidad trimestral, pero para hacer manejable la cantidad de información, se determinó tomarla de manera quinquenal. | Q35: =[1]Económica!AE8 -> Datos vigentes por periodicidad quinquenal. La fuente de información tiene periodicidad trimestral, pero para hacer manejable la cantidad de información, se determinó tomarla de manera quinquenal.
A36: 28 | B36: Económica | C36: Población asalariada y no asalariada según sexo | D36: Porcentaje estatal de la población trabajadora con percepciones no salariales | E36: =[1]Económica!E9 -> Porcentaje de población trabajadora con percepciones no salariales, por entidad federativa. | F36: =[1]Económica!F9 -> 2005, 2010, 2015 y 2020. | G36: =[1]Económica!G9 -> Estatal | H36: =[1]Económica!H9 -> Distribución porcentual de población de 15 y más años de edad, que trabajaron en su propio negocio, empresa, establecimiento o predio agrícola (incluye a las personas que trabajaron sin pago en el negocio o predio familiar o no familiar) (subordinadas y remuneradas), en la fecha de referencia al levantamiento por entidad federativa. | I36: =[1]Económica!I9 -> Por posición en el trabajo. | J36: =[1]Económica!J9 -> Promedio anual de la población de 15 y más años de edad ocupada subordinada remunerada no asalariada, es decir, que trabajaron en su propio negocio, empresa, establecimiento o predio agrícola (incluye a las personas que trabajaron sin pago en el negocio o predio familiar o no familiar) (subordinadas y remuneradas), entre el total de la población ocupada de cada entidad federativa, multiplicado por 100. | K36: =[1]Económica!K9 -> Cálculos por el Colegio de Geografía (UNAM) y de la CNDH a partir de la información del Instituto Nacional de Estadística y Geografía (INEGI) | L36: =[1]Económica!L9 -> Porcentaje | ... P36: =[1]Económica!P9 -> 1. Para el 2020, el promedio no integra el 2o trimestre por suspensión de la ENOE por contigencia sanitaria de COVID-19. 2. La fuente de información tiene periodicidad trimestral, pero para hacer manejable la cantidad de información, se determinó tomarla de manera quinquenal. | Q36: =[1]Económica!AE9 -> Datos vigentes por periodicidad quinquenal. La fuente de información tiene periodicidad trimestral, pero para hacer manejable la cantidad de información, se determinó tomarla de manera quinquenal.
A37: 29 | B37: Económica | C37: Población asalariada y no asalariada según sexo | D37: Porcentaje estatal de mujeres trabajadoras con percepciones no salariales | E37: =[1]Económica!E10 -> Porcentaje de mujeres trabajadoras con percepciones no salariales, por entidad federativa. | F37: =[1]Económica!F10 -> 2005, 2010, 2015 y 2020. | G37: =[1]Económica!G10 -> Estatal | H37: =[1]Económica!H10 -> Distribución porcentual de mujeres de 15 y más años de edad, que trabajaron en su propio negocio, empresa, establecimiento o predio agrícola (incluye a las personas que trabajaron sin pago en el negocio o predio familiar o no familiar) (subordinadas y remuneradas), en la fecha de referencia al levantamiento por entidad federativa. | I37: =[1]Económica!I10 -> Por sexo y posición en el trabajo. | J37: =[1]Económica!J10 -> Promedio anual de la población según sexo (mujeres/hombres) de 15 y más años de edad ocupada subordinada remunerada no asalariada, es decir, que trabajaron en su propio negocio, empresa, establecimiento o predio agrícola (incluye a las personas que trabajaron sin pago en el negocio o predio familiar o no familiar) (subordinadas y remuneradas), entre el total de la población ocupada de cada entidad federativa, multiplicado por 100. | K37: =[1]Económica!K10 -> Cálculos por el Colegio de Geografía (UNAM) y de la CNDH a partir de la información del Instituto Nacional de Estadística y Geografía (INEGI) | L37: =[1]Económica!L10 -> Porcentaje | ... P37: =[1]Económica!P10 -> 1. Para el 2020, el promedio no integra el 2o trimestre por suspensión de la ENOE por contigencia sanitaria de COVID-19. 2. La fuente de información tiene periodicidad trimestral, pero para hacer manejable la cantidad de información, se determinó tomarla de manera quinquenal. | Q37: =[1]Económica!AE10 -> Datos vigentes por periodicidad quinquenal. La fuente de información tiene periodicidad trimestral, pero para hacer manejable la cantidad de información, se determinó tomarla de manera quinquenal.
A38: 30 | B38: Económica | C38: Población asalariada y no asalariada según sexo | D38: Porcentaje estatal de hombres trabajadores con percepciones no salariales | E38: =[1]Económica!E11 -> Porcentaje de hombres trabajadores con percepciones no salariales, por entidad federativa. | F38: =[1]Económica!F11 -> 2005, 2010, 2015 y 2020. | G38: =[1]Económica!G11 -> Estatal | H38: =[1]Económica!H11 -> Distribución porcentual de hombres de 15 y más años de edad, que trabajaron en su propio negocio, empresa, establecimiento o predio agrícola (incluye a las personas que trabajaron sin pago en el negocio o predio familiar o no familiar) (subordinadas y remuneradas), en la fecha de referencia al levantamiento por entidad federativa. | I38: =[1]Económica!I11 -> Por sexo y posición en el trabajo. | J38: =[1]Económica!J11 -> Promedio anual de la población según sexo (mujeres/hombres) de 15 y más años de edad ocupada subordinada remunerada no asalariada, es decir, que trabajaron en su propio negocio, empresa, establecimiento o predio agrícola (incluye a las personas que trabajaron sin pago en el negocio o predio familiar o no familiar) (subordinadas y remuneradas), entre el total de la población ocupada de cada entidad federativa, multiplicado por 100. | K38: =[1]Económica!K11 -> Cálculos por el Colegio de Geografía (UNAM) y de la CNDH a partir de la información del Instituto Nacional de Estadística y Geografía (INEGI) | L38: =[1]Económica!L11 -> Porcentaje | ... P38: =[1]Económica!P11 -> 1. Para el 2020, el promedio no integra el 2o trimestre por suspensión de la ENOE por contigencia sanitaria de COVID-19. 2. La fuente de información tiene periodicidad trimestral, pero para hacer manejable la cantidad de información, se determinó tomarla de manera quinquenal. | Q38: =[1]Económica!AE11 -> Datos vigentes por periodicidad quinquenal. La fuente de información tiene periodicidad trimestral, pero para hacer manejable la cantidad de información, se determinó tomarla de manera quinquenal.
A39: 31 | B39: Económica | C39: Población ocupada según sexo | D39: Porcentaje estatal de mujeres ocupadas | E39: =[1]Económica!E12 -> Porcentaje de mujeres ocupadas, por entidad federativa. | F39: =[1]Económica!F12 -> 2005, 2010, 2015 y 2020. | G39: =[1]Económica!G12 -> Estatal | H39: =[1]Económica!H12 -> Distribución porcentual de mujeres de 15 y más años de edad ocupadas, es decir, que durante la semana de referencia presentaron una de las siguientes situaciones: trabajaron al menos una hora o un día para producir bienes y servicios a cambio de una remuneración monetaria o en especie; tenían empleo pero no trabajaron por alguna causa sin dejar de percibir su ingreso; tenían empleo pero no trabajaron por alguna causa, dejando de percibir su ingreso pero con retorno asegurado a su trabajo en menos de 4 semanas; no tenían empleo, pero iniciarán con seguridad uno en 4 semanas o menos; trabajaron al menos una hora o un día en la semana de referencia, sin recibir pago alguno (ni monetario ni en especie) en un negocio propiedad de un familiar o no familiar, en la fecha de referencia al levantamiento por entidad federativa. | I39: =[1]Económica!I12 -> Por sexo. | J39: =[1]Económica!J12 -> Promedio anual de la población ocupada según sexo (mujeres/hombres), entre el promedio anual de la población ocupada total, multiplicado por 100. | K39: =[1]Económica!K12 -> Cálculos por el Colegio de Geografía (UNAM) y de la CNDH a partir de la información del Instituto Nacional de Estadística y Geografía (INEGI) | L39: =[1]Económica!L12 -> Porcentaje | ... P39: =[1]Económica!P12 -> 1. Para el 2020, el promedio no integra el 2o trimestre por suspensión de la ENOE por contigencia sanitaria de COVID-19. 2. La fuente de información tiene periodicidad trimestral, pero para hacer manejable la cantidad de información, se determinó tomarla de manera quinquenal. | Q39: =[1]Económica!AE12 -> Datos vigentes por periodicidad quinquenal. La fuente de información tiene periodicidad trimestral, pero para hacer manejable la cantidad de información, se determinó tomarla de manera quinquenal.
A40: 32 | B40: Económica | C40: Población ocupada según sexo | D40: Porcentaje estatal de hombres ocupados | E40: =[1]Económica!E13 -> Porcentaje de hombres ocupados, por entidad federativa. | F40: =[1]Económica!F13 -> 2005, 2010, 2015 y 2020. | G40: =[1]Económica!G13 -> Estatal | H40: =[1]Económica!H13 -> Distribución porcentual de hombres de 15 y más años de edad ocupados, es decir, que durante la semana de referencia presentaron una de las siguientes situaciones: trabajaron al menos una hora o un día para producir bienes y servicios a cambio de una remuneración monetaria o en especie; tenían empleo pero no trabajaron por alguna causa sin dejar de percibir su ingreso; tenían empleo pero no trabajaron por alguna causa, dejando de percibir su ingreso pero con retorno asegurado a su trabajo en menos de 4 semanas; no tenían empleo, pero iniciarán con seguridad uno en 4 semanas o menos; trabajaron al menos una hora o un día en la semana de referencia, sin recibir pago alguno (ni monetario ni en especie) en un negocio propiedad de un familiar o no familiar, en la fecha de referencia al levantamiento por entidad federativa. | I40: =[1]Económica!I13 -> Por sexo. | J40: =[1]Económica!J13 -> Promedio anual de la población ocupada según sexo (mujeres/hombres), entre el promedio anual de la población ocupada total, multiplicado por 100. | K40: =[1]Económica!K13 -> Cálculos por el Colegio de Geografía (UNAM) y de la CNDH a partir de la información del Instituto Nacional de Estadística y Geografía (INEGI) | L40: =[1]Económica!L13 -> Porcentaje | ... P40: =[1]Económica!P13 -> 1. Para el 2020, el promedio no integra el 2o trimestre por suspensión de la ENOE por contigencia sanitaria de COVID-19. 2. La fuente de información tiene periodicidad trimestral, pero para hacer manejable la cantidad de información, se determinó tomarla de manera quinquenal. | Q40: =[1]Económica!AE13 -> Datos vigentes por periodicidad quinquenal. La fuente de información tiene periodicidad trimestral, pero para hacer manejable la cantidad de información, se determinó tomarla de manera quinquenal.
A41: 33 | B41: Económica | C41: Población ocupada por nivel de ingreso según sexo | D41: Porcentaje estatal de la población que recibe hasta un salario mínimo | E41: =[1]Económica!E14 -> Porcentaje de población que recibe hasta un salario mínimo, por entidad federativa. | F41: =[1]Económica!F14 -> 2005, 2010, 2015 y 2020. | G41: =[1]Económica!G14 -> Estatal | H41: =[1]Económica!H14 -> Distribución porcentual de la población total en función del nivel de ingreso según el número de salarios que recibe, en la fecha de referencia al levantamiento por entidad federativa. | I41: =[1]Económica!I14 -> Por nivel de ingreso. | J41: =[1]Económica!J14 -> Promedio anual de la población ocupada de 12 y más años de edad según sexo (mujeres/hombres), por rango salarial que reciben (Hasta un S.M.; más de 1 y hasta 2 S.M.; más de 2 hasta 3 S.M.; más de 3 hasta 5 S.M.; más de 5 S.M.), entre el promedio anua de la población ocupada total, multiplicado por 100. | K41: =[1]Económica!K14 -> Cálculos por el Colegio de Geografía (UNAM) y de la CNDH a partir de la información del Instituto Nacional de Estadística y Geografía (INEGI) | L41: =[1]Económica!L14 -> Porcentaje | ... P41: =[1]Económica!P14 -> 1. Para el 2020, el promedio no integra el 2o trimestre por suspensión de la ENOE por contigencia sanitaria de COVID-19. 2. La fuente de información tiene periodicidad trimestral, pero para hacer manejable la cantidad de información, se determinó tomarla de manera quinquenal. Abreviatura S.M.: salario mínimo. | Q41: =[1]Económica!AE14 -> Datos vigentes por periodicidad quinquenal. La fuente de información tiene periodicidad trimestral, pero para hacer manejable la cantidad de información, se determinó tomarla de manera quinquenal.
A42: 34 | B42: Económica | C42: Población ocupada por nivel de ingreso según sexo | D42: Porcentaje estatal de mujeres que reciben hasta un salario mínimo | E42: =[1]Económica!E15 -> Porcentaje de mujeres que su nivel de ingreso es hasta un salario mínimo, por entidad federativa. | F42: =[1]Económica!F15 -> 2005, 2010, 2015 y 2020. | G42: =[1]Económica!G15 -> Estatal | H42: =[1]Económica!H15 -> Distribución porcentual de mujeres en función del nivel de ingreso según el número de salarios que recibe, en la fecha de referencia al levantamiento por entidad federativa. | I42: =[1]Económica!I15 -> Por sexo y nivel de ingreso | J42: =[1]Económica!J15 -> Promedio anual de la población ocupada de 12 y más años de edad según sexo (mujeres/hombres), por rango salarial que reciben (Hasta un S.M.; más de 1 y hasta 2 S.M.; más de 2 hasta 3 S.M.; más de 3 hasta 5 S.M.; más de 5 S.M.), entre el promedio anua de la población ocupada total, multiplicado por 100. | K42: =[1]Económica!K15 -> Cálculos por el Colegio de Geografía (UNAM) y de la CNDH a partir de la información del Instituto Nacional de Estadística y Geografía (INEGI) | L42: =[1]Económica!L15 -> Porcentaje | ... P42: =[1]Económica!P15 -> 1. Para el 2020, el promedio no integra el 2o trimestre por suspensión de la ENOE por contigencia sanitaria de COVID-19. 2. La fuente de información tiene periodicidad trimestral, pero para hacer manejable la cantidad de información, se determinó tomarla de manera quinquenal. Abreviatura S.M.: salario mínimo. | Q42: =[1]Económica!AE15 -> Datos vigentes por periodicidad quinquenal. La fuente de información tiene periodicidad trimestral, pero para hacer manejable la cantidad de información, se determinó tomarla de manera quinquenal.
... A77: 69 | B77: Económica | C77: Total de hogares según sexo de jefatura de familia | D77: Porcentaje estatal de hogares con jefatura de familia masculina | E77: =[1]Económica!E50 -> Porcentaje de hogares con jefatura de familia masculina, por entidad federativa. | F77: =[1]Económica!F50 -> 2005, 2010, 2015 y 2020 | G77: =[1]Económica!G50 -> Estatal | H77: =[1]Económica!H50 -> Distribución porcentual de viviendas particulares habitadas con jefatura de hogar masculina, en la fecha de referencia al levantamiento por entidad federativa. | I77: =[1]Económica!I50 -> Por sexo | J77: =[1]Económica!J50 -> Suma de las viviendas particulares habitadas según sexo de jefatura de hogar (mujeres/hombres), entre el total de viviendas particulares habitadas, multiplicado por 100. | K77: =[1]Económica!K50 -> Cálculos por el Colegio de Geografía (UNAM) y de la CNDH a partir de la información del Instituto Nacional de Estadística y Geografía (INEGI) | L77: =[1]Económica!L50 -> Porcentaje | ... P77: =[1]Económica!P50 -> 0 | Q77: =[1]Económica!AE50 -> Datos vigentes por periodicidad quinquenal.
A78: 70 | B78: Económica | C78: Población en situación de pobreza según sexo | D78: Porcentaje estatal de la población en situación de pobreza | E78: =[1]Económica!E52 -> Porcentaje de la población en situación de pobreza, por entidad federativa. | F78: =[1]Económica!F52 -> 2008, 2010, 2012, 2014, 2016, 2018, 2020 y 2022. | G78: =[1]Económica!G52 -> Estatal | H78: =[1]Económica!H52 -> Distribución porcentual de la población que tiene al menos una carencia social (en los seis indicadores de rezago educativo, acceso a servicios de salud, acceso a la seguridad social, calidad y espacios de la vivienda, servicios básicos en la vivienda y acceso a la alimentación) y su ingreso es insuficiente para adquirir los bienes y servicios que requiere para satisfacer sus necesidades alimentarias y no alimentarias, en la fecha de referencia al levantamiento por entidad federativa. | I78: =[1]Económica!I52 -> Por nivel de pobreza. | J78: =[1]Económica!J52 -> Distribución porcentual de la población en situación de pobreza, es decir, cuando tiene al menos una carencia social (en los seis indicadores de rezago educativo, acceso a servicios de salud, acceso a la seguridad social, calidad y espacios de la vivienda, servicios básicos en la vivienda y acceso a la alimentación) y su ingreso es insuficiente para adquirir los bienes y servicios que requiere para satisfacer sus necesidades alimentarias y no alimentarias, entre el total de la población, multiplicado por 100. | K78: =[1]Económica!K52 -> Cálculos por el Colegio de Geografía (UNAM) y de la CNDH a partir de la información de las estimaciones del Consejo Nacional de Evaluación de la Política de Desarrollo Social (CONEVAL), con base en el Módulo de Condiciones Socioeconómicas (MCS) de la Encuesta Nacional de Ingresos y Gastos de los Hogares (ENIGH) y el Modelo Estadístico 2016 para la continuidad del MCS-ENIGH. | L78: =[1]Económica!L52 -> Porcentaje | ... P78: =[1]Económica!P52 -> Con corte al segundo trimestre de 2024, la fuente oficial de información no cuenta con actualización de datos. | Q78: =[1]Económica!AE52 -> Datos vigentes por periodicidad bianual, sin embargo, la fuente oficial de información no cuenta con actualización de datos.
A79: 71 | B79: Económica | C79: Población en situación de pobreza según sexo | D79: Porcentaje estatal de mujeres en situación de pobreza | E79: =[1]Económica!E53 -> Porcentaje de mujeres en situación de pobreza, por entidad federativa. | F79: =[1]Económica!F53 -> 2008, 2010, 2012, 2014, 2016, 2018, 2020 y 2022. | G79: =[1]Económica!G53 -> Estatal | H79: =[1]Económica!H53 -> Distribución porcentual de mujeres que tiene al menos una carencia social (en los seis indicadores de rezago educativo, acceso a servicios de salud, acceso a la seguridad social, calidad y espacios de la vivienda, servicios básicos en la vivienda y acceso a la alimentación) y su ingreso es insuficiente para adquirir los bienes y servicios que requiere para satisfacer sus necesidades alimentarias y no alimentarias, en la fecha de referencia al levantamiento por entidad federativa. | I79: =[1]Económica!I53 -> Por sexo y nivel de pobreza. | J79: =[1]Económica!J53 -> Distribución porcentual de la población según sexo (mujeres/hombres) en situación de pobreza, es decir, cuando tiene al menos una carencia social (en los seis indicadores de rezago educativo, acceso a servicios de salud, acceso a la seguridad social, calidad y espacios de la vivienda, servicios básicos en la vivienda y acceso a la alimentación) y su ingreso es insuficiente para adquirir los bienes y servicios que requiere para satisfacer sus necesidades alimentarias y no alimentarias, entre el total de la población según sexo (mujeres/hombres), multiplicado por 100. | K79: =[1]Económica!K53 -> Cálculos por el Colegio de Geografía (UNAM) y de la CNDH a partir de la información de las estimaciones del Consejo Nacional de Evaluación de la Política de Desarrollo Social (CONEVAL), con base en el Módulo de Condiciones Socioeconómicas (MCS) de la Encuesta Nacional de Ingresos y Gastos de los Hogares (ENIGH) y el Modelo Estadístico 2016 para la continuidad del MCS-ENIGH. | L79: =[1]Económica!L53 -> Porcentaje | ... P79: =[1]Económica!P53 -> Con corte al segundo trimestre de 2024, la fuente oficial de información no cuenta con actualización de datos. | Q79: =[1]Económica!AE53 -> Datos vigentes por periodicidad bianual, sin embargo, la fuente oficial de información no cuenta con actualización de datos.
A80: 72 | B80: Económica | C80: Población en situación de pobreza según sexo | D80: Porcentaje estatal de hombres en situación de pobreza | E80: =[1]Económica!E54 -> Porcentaje de hombres en situación de pobreza, por entidad federativa. | F80: =[1]Económica!F54 -> 2008, 2010, 2012, 2014, 2016, 2018, 2020 y 2022. | G80: =[1]Económica!G54 -> Estatal | H80: =[1]Económica!H54 -> Distribución porcentual de hombres que tiene al menos una carencia social (en los seis indicadores de rezago educativo, acceso a servicios de salud, acceso a la seguridad social, calidad y espacios de la vivienda, servicios básicos en la vivienda y acceso a la alimentación) y su ingreso es insuficiente para adquirir los bienes y servicios que requiere para satisfacer sus necesidades alimentarias y no alimentarias, en la fecha de referencia al levantamiento por entidad federativa. | I80: =[1]Económica!I54 -> Por sexo y nivel de pobreza. | J80: =[1]Económica!J54 -> Distribución porcentual de la población según sexo (mujeres/hombres) en situación de pobreza, es decir, cuando tiene al menos una carencia social (en los seis indicadores de rezago educativo, acceso a servicios de salud, acceso a la seguridad social, calidad y espacios de la vivienda, servicios básicos en la vivienda y acceso a la alimentación) y su ingreso es insuficiente para adquirir los bienes y servicios que requiere para satisfacer sus necesidades alimentarias y no alimentarias, entre el total de la población según sexo (mujeres/hombres), multiplicado por 100. | K80: =[1]Económica!K54 -> Cálculos por el Colegio de Geografía (UNAM) y de la CNDH a partir de la información de las estimaciones del Consejo Nacional de Evaluación de la Política de Desarrollo Social (CONEVAL), con base en el Módulo de Condiciones Socioeconómicas (MCS) de la Encuesta Nacional de Ingresos y Gastos de los Hogares (ENIGH) y el Modelo Estadístico 2016 para la continuidad del MCS-ENIGH. | L80: =[1]Económica!L54 -> Porcentaje | ... P80: =[1]Económica!P54 -> Con corte al segundo trimestre de 2024, la fuente oficial de información no cuenta con actualización de datos. | Q80: =[1]Económica!AE54 -> Datos vigentes por periodicidad bianual, sin embargo, la fuente oficial de información no cuenta con actualización de datos.
A81: 73 | B81: Económica | C81: Población en situación de pobreza según sexo | D81: Porcentaje estatal de la población en situación de pobreza moderada | E81: =[1]Económica!E55 -> Porcentaje de la población en situación de pobreza moderada, por entidad federativa. | F81: =[1]Económica!F55 -> 2008, 2010, 2012, 2014, 2016, 2018, 2020 y 2022. | G81: =[1]Económica!G55 -> Estatal | H81: =[1]Económica!H55 -> Distribución porcentual de la población que, de acuerdo a CONEVAL, siendo pobre, no es pobre extrema (la incidencia de pobreza moderada se obtiene al calcular la diferencia entre la incidencia de la población en pobreza menos la de la población en pobreza extrema), en la fecha de referencia al levantamiento por entidad federativa. | I81: =[1]Económica!I55 -> Por nivel de pobreza. | J81: =[1]Económica!J55 -> Distribución porcentual de la población en situación de pobreza moderada, entre el total de la población en situación de pobreza, multiplicado por 100. | K81: =[1]Económica!K55 -> Cálculos por el Colegio de Geografía (UNAM) y de la CNDH a partir de la información de las estimaciones del Consejo Nacional de Evaluación de la Política de Desarrollo Social (CONEVAL), con base en el Módulo de Condiciones Socioeconómicas (MCS) de la Encuesta Nacional de Ingresos y Gastos de los Hogares (ENIGH) y el Modelo Estadístico 2016 para la continuidad del MCS-ENIGH. | L81: =[1]Económica!L55 -> Porcentaje | ... P81: =[1]Económica!P55 -> Con corte al segundo trimestre de 2024, la fuente oficial de información no cuenta con actualización de datos. | Q81: =[1]Económica!AE55 -> Datos vigentes por periodicidad bianual, sin embargo, la fuente oficial de información no cuenta con actualización de datos.
A82: 74 | B82: Económica | C82: Población en situación de pobreza según sexo | D82: Porcentaje estatal de mujeres en situación de pobreza moderada | E82: =[1]Económica!E56 -> Porcentaje de mujeres en situación de pobreza moderada, por entidad federativa. | F82: =[1]Económica!F56 -> 2008, 2010, 2012, 2014, 2016, 2018, 2020 y 2022. | G82: =[1]Económica!G56 -> Estatal | H82: =[1]Económica!H56 -> Distribución porcentual de mujeres que, de acuerdo a CONEVAL, siendo pobre, no es pobre extrema (la incidencia de pobreza moderada se obtiene al calcular la diferencia entre la incidencia de la población en pobreza menos la de la población en pobreza extrema), en la fecha de referencia al levantamiento por entidad federativa. | I82: =[1]Económica!I56 -> Por sexo y nivel de pobreza. | J82: =[1]Económica!J56 -> Distribución porcentual de la población según sexo (mujeres/hombres) en situación de pobreza moderada, entre el total de la población en situación de pobreza según sexo (mujeres/hombres), multiplicado por 100. | K82: =[1]Económica!K56 -> Cálculos por el Colegio de Geografía (UNAM) y de la CNDH a partir de la información de las estimaciones del Consejo Nacional de Evaluación de la Política de Desarrollo Social (CONEVAL), con base en el Módulo de Condiciones Socioeconómicas (MCS) de la Encuesta Nacional de Ingresos y Gastos de los Hogares (ENIGH) y el Modelo Estadístico 2016 para la continuidad del MCS-ENIGH. | L82: =[1]Económica!L56 -> Porcentaje | ... P82: =[1]Económica!P56 -> Con corte al segundo trimestre de 2024, la fuente oficial de información no cuenta con actualización de datos. | Q82: =[1]Económica!AE56 -> Datos vigentes por periodicidad bianual, sin embargo, la fuente oficial de información no cuenta con actualización de datos.
A83: 75 | B83: Económica | C83: Población en situación de pobreza según sexo | D83: Porcentaje estatal de hombres en situación de pobreza moderada | E83: =[1]Económica!E57 -> Porcentaje de hombres en situación de pobreza moderada, por entidad federativa. | F83: =[1]Económica!F57 -> 2008, 2010, 2012, 2014, 2016, 2018, 2020 y 2022. | G83: =[1]Económica!G57 -> Estatal | H83: =[1]Económica!H57 -> Distribución porcentual de hombres que, de acuerdo a CONEVAL, siendo pobre, no es pobre extrema (la incidencia de pobreza moderada se obtiene al calcular la diferencia entre la incidencia de la población en pobreza menos la de la población en pobreza extrema), en la fecha de referencia al levantamiento por entidad federativa. | I83: =[1]Económica!I57 -> Por sexo y nivel de pobreza. | J83: =[1]Económica!J57 -> Distribución porcentual de la población según sexo (mujeres/hombres) en situación de pobreza moderada, entre el total de la población en situación de pobreza según sexo (mujeres/hombres), multiplicado por 100. | K83: =[1]Económica!K57 -> Cálculos por el Colegio de Geografía (UNAM) y de la CNDH a partir de la información de las estimaciones del Consejo Nacional de Evaluación de la Política de Desarrollo Social (CONEVAL), con base en el Módulo de Condiciones Socioeconómicas (MCS) de la Encuesta Nacional de Ingresos y Gastos de los Hogares (ENIGH) y el Modelo Estadístico 2016 para la continuidad del MCS-ENIGH. | L83: =[1]Económica!L57 -> Porcentaje | ... P83: =[1]Económica!P57 -> Con corte al segundo trimestre de 2024, la fuente oficial de información no cuenta con actualización de datos. | Q83: =[1]Económica!AE57 -> Datos vigentes por periodicidad bianual, sin embargo, la fuente oficial de información no cuenta con actualización de datos.
A84: 76 | B84: Económica | C84: Población en situación de pobreza según sexo | D84: Porcentaje estatal de la población en situación de pobreza extrema | E84: =[1]Económica!E58 -> Porcentaje de la población en situación de pobreza extrema, por entidad federativa. | F84: =[1]Económica!F58 -> 2008, 2010, 2012, 2014, 2016, 2018, 2020 y 2022. | G84: =[1]Económica!G58 -> Estatal | H84: =[1]Económica!H58 -> Distribución porcentual de la población que tiene tres o más carencias, de seis posibles, dentro del Índice de Privación Social y que, además, se encuentra por debajo de la línea de bienestar mínimo (las personas en esta situación disponen de un ingreso tan bajo que, aun si lo dedicase por completo a la adquisición de alimentos, no podría adquirir los nutrientes necesarios para tener una vida sana), en la fecha de referencia al levantamiento por entidad federativa. | I84: =[1]Económica!I58 -> Por nivel de pobreza. | J84: =[1]Económica!J58 -> Distribución porcentual de la población en situación de pobreza extrema, es decir, que tiene tres o más carencias, de seis posibles, dentro del Índice de Privación Social y que, además, se encuentra por debajo de la línea de bienestar mínimo (las personas en esta situación disponen de un ingreso tan bajo que, aun si lo dedicase por completo a la adquisición de alimentos, no podría adquirir los nutrientes necesarios para tener una vida sana), entre el total de la población en situación de pobreza, multiplicado por 100. | K84: =[1]Económica!K58 -> Cálculos por el Colegio de Geografía (UNAM) y de la CNDH a partir de la información de las estimaciones del Consejo Nacional de Evaluación de la Política de Desarrollo Social (CONEVAL), con base en el Módulo de Condiciones Socioeconómicas (MCS) de la Encuesta Nacional de Ingresos y Gastos de los Hogares (ENIGH) y el Modelo Estadístico 2016 para la continuidad del MCS-ENIGH. | L84: =[1]Económica!L58 -> Porcentaje | ... P84: =[1]Económica!P58 -> Con corte al segundo trimestre de 2024, la fuente oficial de información no cuenta con actualización de datos. | Q84: =[1]Económica!AE58 -> Datos vigentes por periodicidad bianual, sin embargo, la fuente oficial de información no cuenta con actualización de datos.
A85: 77 | B85: Económica | C85: Población en situación de pobreza según sexo | D85: Porcentaje estatal de mujeres en situación de pobreza extrema | E85: =[1]Económica!E59 -> Porcentaje de mujeres en situación de pobreza extrema, por entidad federativa. | F85: =[1]Económica!F59 -> 2008, 2010, 2012, 2014, 2016, 2018, 2020 y 2022. | G85: =[1]Económica!G59 -> Estatal | H85: =[1]Económica!H59 -> Distribución porcentual de mujeres que tiene tres o más carencias, de seis posibles, dentro del Índice de Privación Social y que, además, se encuentra por debajo de la línea de bienestar mínimo (las personas en esta situación disponen de un ingreso tan bajo que, aun si lo dedicase por completo a la adquisición de alimentos, no podría adquirir los nutrientes necesarios para tener una vida sana), en la fecha de referencia al levantamiento por entidad federativa. | I85: =[1]Económica!I59 -> Por sexo y nivel de pobreza. | J85: =[1]Económica!J59 -> Distribución porcentual de la población según sexo (mujeres/hombres) en situación de pobreza extrema, es decir, que tiene tres o más carencias, de seis posibles, dentro del Índice de Privación Social y que, además, se encuentra por debajo de la línea de bienestar mínimo (las personas en esta situación disponen de un ingreso tan bajo que, aun si lo dedicase por completo a la adquisición de alimentos, no podría adquirir los nutrientes necesarios para tener una vida sana), entre el total de la población en situación de pobreza según sexo (mujeres/hombres), multiplicado por 100. | K85: =[1]Económica!K59 -> Cálculos por el Colegio de Geografía (UNAM) y de la CNDH a partir de la información de las estimaciones del Consejo Nacional de Evaluación de la Política de Desarrollo Social (CONEVAL), con base en el Módulo de Condiciones Socioeconómicas (MCS) de la Encuesta Nacional de Ingresos y Gastos de los Hogares (ENIGH) y el Modelo Estadístico 2016 para la continuidad del MCS-ENIGH. | L85: =[1]Económica!L59 -> Porcentaje | ... P85: =[1]Económica!P59 -> Con corte al segundo trimestre de 2024, la fuente oficial de información no cuenta con actualización de datos. | Q85: =[1]Económica!AE59 -> Datos vigentes por periodicidad bianual, sin embargo, la fuente oficial de información no cuenta con actualización de datos.
...
